<?xml version="1.0"?>
<robot name="qube_robot" xmlns:xacro="http://www.ros.org/wiki/xacro">

  <!-- Globale materialer -->
  <material name="black">
    <color rgba="0 0 0 1"/>
  </material>
  <material name="red">
    <color rgba="1 0 0 1"/>
  </material>
  <material name="white">
    <color rgba="1 1 1 1"/>
  </material>

  <!-- Makro-parametre -->
  <xacro:property name="base_length" value="0.102" />
  <xacro:property name="disk_radius" value="0.025" />
  <xacro:property name="disk_height" value="0.01" />
  <xacro:property name="pointer_length" value="0.025" />
  <xacro:property name="pointer_height" value="0.02" />

  <xacro:macro name="qube">
    <!-- Base link og joint -->
    <link name="base_link">
      <visual>
        <geometry>
          <box size="${base_length} ${base_length} ${base_length}"/>
        </geometry>
        <material name="black"/>
      </visual>
    </link>

    <joint name="base_joint" type="fixed">
      <parent link="base_link"/>
      <child link="rotating_disk"/>
      <origin xyz="0 0 0.051" rpy="0 0 0"/>
    </joint>

    <!-- Roterende disk link og joint -->
    <link name="rotating_disk">
        <visual>
            <geometry>
                <cylinder radius="0.025" length="0.01"/>
            </geometry>
            <material name="red"/>
        </visual>
    </link>

    <joint name="motor_joint" type="continuous">
      <parent link="base_link"/>
      <child link="rotating_disk"/>
      <origin xyz="0 0 0.056" rpy="0 0 0"/>
      <axis xyz="0 0 1"/>
      <limit lower="-3.14" upper="3.14" effort="10" velocity="5"/>
    </joint>

    <!-- Hvit viser link og joint -->
    <link name="pointer">
        <visual>
            <geometry>
                <box size="0.025 0.002 0.002"/>
            </geometry>
            <material name="white"/>
        </visual>
    </link>

    <joint name="pointer_joint" type="fixed">
      <parent link="rotating_disk"/>
      <child link="pointer"/>
      <origin xyz="0.0125 0 0.006" rpy="0 0 0"/>
    </joint>
  </xacro:macro>
</robot>